<?xml version="1.0" encoding="utf-8"?>
<!-- This URDF was automatically created by SolidWorks to URDF Exporter! Originally created by Stephen Brawner (brawner@gmail.com) 
     Commit Version: 1.5.1-0-g916b5db  Build Version: 1.5.7152.31018
     For more information, please see http://wiki.ros.org/sw_urdf_exporter -->
<robot
  name="boris_description">
  <link
    name="base_link">
    <inertial>
      <origin
        xyz="-0.022939618276426 0.000126889427596712 0.114856317470281"
        rpy="0 0 0" />
      <mass
        value="6.25092338139406" />
      <inertia
        ixx="0.157012634394671"
        ixy="4.17420320914166E-07"
        ixz="-1.16452308907686E-06"
        iyy="0.157875862434322"
        iyz="-3.92278672942607E-08"
        izz="0.231739535357394" />
    </inertial>
    <visual>
      <origin
        xyz="0 0 0"
        rpy="0 0 0" />
      <geometry>
        <mesh
          filename="package://boris_description/meshes/base_link.STL" />
      </geometry>
      <material
        name="">
        <color
          rgba="0.898039215686275 0.917647058823529 0.929411764705882 1" />
      </material>
    </visual>
    <collision>
      <origin
        xyz="0 0 0"
        rpy="0 0 0" />
      <geometry>
        <mesh
          filename="package://boris_description/meshes/base_link.STL" />
      </geometry>
    </collision>
  </link>
  <link
    name="left_wheel_link">
    <inertial>
      <origin
        xyz="0.0298553485818144 -7.38981511210325E-14 -7.28085556632452E-06"
        rpy="0 0 0" />
      <mass
        value="0.958008587347379" />
      <inertia
        ixx="0.00270268789560969"
        ixy="-1.01480767286744E-14"
        ixz="-3.83317404192863E-07"
        iyy="0.00158533951189093"
        iyz="4.46797081233784E-16"
        izz="0.00158537445467052" />
    </inertial>
    <visual>
      <origin
        xyz="0 0 0"
        rpy="0 0 0" />
      <geometry>
        <mesh
          filename="package://boris_description/meshes/left_wheel_link.STL" />
      </geometry>
      <material
        name="">
        <color
          rgba="0.792156862745098 0.819607843137255 0.933333333333333 1" />
      </material>
    </visual>
    <collision>
      <origin
        xyz="0 0 0"
        rpy="0 0 0" />
      <geometry>
        <mesh
          filename="package://boris_description/meshes/left_wheel_link.STL" />
      </geometry>
    </collision>
  </link>
  <joint
    name="left_wheel_joint"
    type="continuous">
    <origin
      xyz="-1.02E-05 0.3074 -0.017901"
      rpy="-3.1416 0 1.5708" />
    <parent
      link="base_link" />
    <child
      link="left_wheel_link" />
    <axis
      xyz="1 0 0" />
  </joint>
  <link
    name="right_wheel_link">
    <inertial>
      <origin
        xyz="0.0298553485818144 -7.38470377648634E-14 -7.28085556632105E-06"
        rpy="0 0 0" />
      <mass
        value="0.958008587347379" />
      <inertia
        ixx="0.0027026878956097"
        ixy="-1.01473571864158E-14"
        ixz="-3.83317404192777E-07"
        iyy="0.00158533951189094"
        iyz="4.49362472967403E-16"
        izz="0.00158537445467052" />
    </inertial>
    <visual>
      <origin
        xyz="0 0 0"
        rpy="0 0 0" />
      <geometry>
        <mesh
          filename="package://boris_description/meshes/right_wheel_link.STL" />
      </geometry>
      <material
        name="">
        <color
          rgba="0.792156862745098 0.819607843137255 0.933333333333333 1" />
      </material>
    </visual>
    <collision>
      <origin
        xyz="0 0 0"
        rpy="0 0 0" />
      <geometry>
        <mesh
          filename="package://boris_description/meshes/right_wheel_link.STL" />
      </geometry>
    </collision>
  </link>
  <joint
    name="right_wheel_joint"
    type="continuous">
    <origin
      xyz="-1.02E-05 -0.3074 -0.017901"
      rpy="3.1416 0 -1.5708" />
    <parent
      link="base_link" />
    <child
      link="right_wheel_link" />
    <axis
      xyz="1 0 0" />
  </joint>
  <link
    name="gps_link">
    <inertial>
      <origin
        xyz="0.000141607368226923 0.00578560617441407 0.00352975276544121"
        rpy="0 0 0" />
      <mass
        value="0.00810471227426635" />
      <inertia
        ixx="1.3563972967208E-06"
        ixy="7.66231332658889E-09"
        ixz="1.5842654379685E-08"
        iyy="2.87742203534793E-06"
        iyz="-7.73428856817732E-08"
        izz="2.04449877493056E-06" />
    </inertial>
    <visual>
      <origin
        xyz="0 0 0"
        rpy="0 0 0" />
      <geometry>
        <mesh
          filename="package://boris_description/meshes/gps_link.STL" />
      </geometry>
      <material
        name="">
        <color
          rgba="0.792156862745098 0.819607843137255 0.933333333333333 1" />
      </material>
    </visual>
    <collision>
      <origin
        xyz="0 0 0"
        rpy="0 0 0" />
      <geometry>
        <mesh
          filename="package://boris_description/meshes/gps_link.STL" />
      </geometry>
    </collision>
  </link>
  <joint
    name="gps_joint"
    type="fixed">
    <origin
      xyz="-0.24281 -0.026225 1.1433"
      rpy="0 0 1.5708" />
    <parent
      link="base_link" />
    <child
      link="gps_link" />
    <axis
      xyz="0 0 0" />
  </joint>
  <link
    name="imu">
    <inertial>
      <origin
        xyz="0.0128931247706793 0.00106324875441682 -0.0102654300276027"
        rpy="0 0 0" />
      <mass
        value="0.000983130183652036" />
      <inertia
        ixx="2.72780814792229E-08"
        ixy="-1.83135757569056E-11"
        ixz="-1.8646371535333E-11"
        iyy="7.48563776021963E-08"
        iyz="1.81575171893248E-12"
        izz="4.80453464098757E-08" />
    </inertial>
    <visual>
      <origin
        xyz="0 0 0"
        rpy="0 0 0" />
      <geometry>
        <mesh
          filename="package://boris_description/meshes/imu.STL" />
      </geometry>
      <material
        name="">
        <color
          rgba="0.792156862745098 0.819607843137255 0.933333333333333 1" />
      </material>
    </visual>
    <collision>
      <origin
        xyz="0 0 0"
        rpy="0 0 0" />
      <geometry>
        <mesh
          filename="package://boris_description/meshes/imu.STL" />
      </geometry>
    </collision>
  </link>
  <joint
    name="imu_joint"
    type="fixed">
    <origin
      xyz="-0.21204 -0.013335 0.20085"
      rpy="1.5708 0 1.5708" />
    <parent
      link="base_link" />
    <child
      link="imu" />
    <axis
      xyz="0 0 0" />
  </joint>
  <link
    name="camera_yaw_link">
    <inertial>
      <origin
        xyz="0.0259503164915985 0.0524809585558006 -0.000244707467082439"
        rpy="0 0 0" />
      <mass
        value="0.0236989643956742" />
      <inertia
        ixx="6.18500861568292E-06"
        ixy="-1.15565378682225E-08"
        ixz="2.22920046214975E-08"
        iyy="3.58533094969821E-06"
        iyz="-7.70649063923888E-08"
        izz="4.50633805652113E-06" />
    </inertial>
    <visual>
      <origin
        xyz="0 0 0"
        rpy="0 0 0" />
      <geometry>
        <mesh
          filename="package://boris_description/meshes/camera_yaw_link.STL" />
      </geometry>
      <material
        name="">
        <color
          rgba="0.898039215686275 0.917647058823529 0.929411764705882 1" />
      </material>
    </visual>
    <collision>
      <origin
        xyz="0 0 0"
        rpy="0 0 0" />
      <geometry>
        <mesh
          filename="package://boris_description/meshes/camera_yaw_link.STL" />
      </geometry>
    </collision>
  </link>
  <joint
    name="camera_yaw_joint"
    type="continuous">
    <origin
      xyz="-0.16095 0 1.1464"
      rpy="-1.5708 0 1.5708" />
    <parent
      link="base_link" />
    <child
      link="camera_yaw_link" />
    <axis
      xyz="0 1 0" />
  </joint>
  <link
    name="camera_tilt_link">
    <inertial>
      <origin
        xyz="0.0493199630854666 -0.0173483331606605 9.47173012134095E-05"
        rpy="0 0 0" />
      <mass
        value="0.0136650343598073" />
      <inertia
        ixx="1.44828626038019E-06"
        ixy="-2.08688729262772E-08"
        ixz="-4.90314729830163E-10"
        iyy="5.20651608944564E-06"
        iyz="8.34838762542022E-22"
        izz="4.83945196946744E-06" />
    </inertial>
    <visual>
      <origin
        xyz="0 0 0"
        rpy="0 0 0" />
      <geometry>
        <mesh
          filename="package://boris_description/meshes/camera_tilt_link.STL" />
      </geometry>
      <material
        name="">
        <color
          rgba="0.898039215686275 0.917647058823529 0.929411764705882 1" />
      </material>
    </visual>
    <collision>
      <origin
        xyz="0 0 0"
        rpy="0 0 0" />
      <geometry>
        <mesh
          filename="package://boris_description/meshes/camera_tilt_link.STL" />
      </geometry>
    </collision>
  </link>
  <joint
    name="camera_tilt_joint"
    type="continuous">
    <origin
      xyz="0.041323 0.061915 0"
      rpy="0 0 3.1416" />
    <parent
      link="camera_yaw_link" />
    <child
      link="camera_tilt_link" />
    <axis
      xyz="1 0 0" />
  </joint>
  <joint name="camera2_joint" type="fixed">
    <origin
      xyz="0.041323 -0.023823 0"
      rpy="3.1416 1.57079632679 1.57079632679" />
    <parent link="camera_tilt_link" />
    <child link="camera2_bottom_screw_frame" />
    <axis xyz="0 0 0" />
  </joint>
  <link name="camera2_bottom_screw_frame"/>
  <joint name="camera2_link_joint" type="fixed">
    <origin rpy="0 0 0" xyz="0 0.0175 0.0125"/>
    <parent link="camera2_bottom_screw_frame"/>
    <child link="camera2_link"/>
  </joint>
  <link name="camera2_link">
    <visual>
      <origin rpy="1.57079632679 0 1.57079632679" xyz="0.0149 -0.0175 0"/>
      <geometry>
        <!-- <box size="${d435_cam_width} ${d435_cam_height} ${d435_cam_depth}"/> -->
        <mesh filename="package://boris_description/meshes/d435.dae"/>
      </geometry>
    </visual>
    <collision>
      <origin rpy="0 0 0" xyz="0 -0.0175 0"/>
      <geometry>
        <box size="0.02505 0.09 0.025"/>
      </geometry>
    </collision>
    <inertial>
      <!-- The following are not reliable values, and should not be used for modeling -->
      <mass value="0.564"/>
      <origin xyz="0 0 0"/>
      <inertia ixx="0.003881243" ixy="0.0" ixz="0.0" iyy="0.000498940" iyz="0.0" izz="0.003879257"/>
    </inertial>
  </link>
  <!-- camera depth joints and links -->
  <joint name="camera2_depth_joint" type="fixed">
    <origin rpy="0 0 0" xyz="0 0 0"/>
    <parent link="camera2_link"/>
    <child link="camera2_depth_frame"/>
  </joint>
  <link name="camera2_depth_frame"/>
  <joint name="camera2_depth_optical_joint" type="fixed">
    <origin rpy="-1.57079632679 0 -1.57079632679" xyz="0 0 0"/>
    <parent link="camera2_depth_frame"/>
    <child link="camera2_depth_optical_frame"/>
  </joint>
  <link name="camera2_depth_optical_frame"/>
  <!-- camera left IR joints and links -->
  <joint name="camera2_infra1_joint" type="fixed">
    <origin rpy="0 0 0" xyz="0 0.0 0"/>
    <parent link="camera2_link"/>
    <child link="camera2_infra1_frame"/>
  </joint>
  <link name="camera2_infra1_frame"/>
  <joint name="camera2_infra1_optical_joint" type="fixed">
    <origin rpy="-1.57079632679 0 -1.57079632679" xyz="0 0 0"/>
    <parent link="camera2_infra1_frame"/>
    <child link="camera2_infra1_optical_frame"/>
  </joint>
  <link name="camera2_infra1_optical_frame"/>
  <!-- camera right IR joints and links -->
  <joint name="camera2_infra2_joint" type="fixed">
    <origin rpy="0 0 0" xyz="0 -0.05 0"/>
    <parent link="camera2_link"/>
    <child link="camera2_infra2_frame"/>
  </joint>
  <link name="camera2_infra2_frame"/>
  <joint name="camera2_infra2_optical_joint" type="fixed">
    <origin rpy="-1.57079632679 0 -1.57079632679" xyz="0 0 0"/>
    <parent link="camera2_infra2_frame"/>
    <child link="camera2_infra2_optical_frame"/>
  </joint>
  <link name="camera2_infra2_optical_frame"/>
  <!-- camera color joints and links -->
  <joint name="camera2_color_joint" type="fixed">
    <origin rpy="0 0 0" xyz="0 0.015 0"/>
    <parent link="camera2_link"/>
    <child link="camera2_color_frame"/>
  </joint>
  <link name="camera2_color_frame"/>
  <joint name="camera2_color_optical_joint" type="fixed">
    <origin rpy="-1.57079632679 0 -1.57079632679" xyz="0 0 0"/>
    <parent link="camera2_color_frame"/>
    <child link="camera2_color_optical_frame"/>
  </joint>
  <link name="camera2_color_optical_frame"/>
  <joint name="camera_joint" type="fixed">
    <origin
      xyz="0.29 0 0.13"
      rpy="3.1416 0 0" />
    <parent link="base_link" />
    <child link="camera_bottom_screw_frame" />
    <axis xyz="0 0 0" />
  </joint>
  <link name="camera_bottom_screw_frame"/>
  <joint name="camera_link_joint" type="fixed">
    <origin rpy="0 0 0" xyz="0 0.0175 0.0125"/>
    <parent link="camera_bottom_screw_frame"/>
    <child link="camera_link"/>
  </joint>
  <link name="camera_link">
    <visual>
      <origin rpy="1.57079632679 0 1.57079632679" xyz="0.0149 -0.0175 0"/>
      <geometry>
        <!-- <box size="${d435_cam_width} ${d435_cam_height} ${d435_cam_depth}"/> -->
        <mesh filename="package://boris_description/meshes/d435.dae"/>
      </geometry>
    </visual>
    <collision>
      <origin rpy="0 0 0" xyz="0 -0.0175 0"/>
      <geometry>
        <box size="0.02505 0.09 0.025"/>
      </geometry>
    </collision>
    <inertial>
      <!-- The following are not reliable values, and should not be used for modeling -->
      <mass value="0.564"/>
      <origin xyz="0 0 0"/>
      <inertia ixx="0.003881243" ixy="0.0" ixz="0.0" iyy="0.000498940" iyz="0.0" izz="0.003879257"/>
    </inertial>
  </link>
  <!-- camera depth joints and links -->
  <joint name="camera_depth_joint" type="fixed">
    <origin rpy="0 0 0" xyz="0 0 0"/>
    <parent link="camera_link"/>
    <child link="camera_depth_frame"/>
  </joint>
  <link name="camera_depth_frame"/>
  <joint name="camera_depth_optical_joint" type="fixed">
    <origin rpy="-1.57079632679 0 -1.57079632679" xyz="0 0 0"/>
    <parent link="camera_depth_frame"/>
    <child link="camera_depth_optical_frame"/>
  </joint>
  <link name="camera_depth_optical_frame"/>
  <!-- camera left IR joints and links -->
  <joint name="camera_infra1_joint" type="fixed">
    <origin rpy="0 0 0" xyz="0 0.0 0"/>
    <parent link="camera_link"/>
    <child link="camera_infra1_frame"/>
  </joint>
  <link name="camera_infra1_frame"/>
  <joint name="camera_infra1_optical_joint" type="fixed">
    <origin rpy="-1.57079632679 0 -1.57079632679" xyz="0 0 0"/>
    <parent link="camera_infra1_frame"/>
    <child link="camera_infra1_optical_frame"/>
  </joint>
  <link name="camera_infra1_optical_frame"/>
  <!-- camera right IR joints and links -->
  <joint name="camera_infra2_joint" type="fixed">
    <origin rpy="0 0 0" xyz="0 -0.05 0"/>
    <parent link="camera_link"/>
    <child link="camera_infra2_frame"/>
  </joint>
  <link name="camera_infra2_frame"/>
  <joint name="camera_infra2_optical_joint" type="fixed">
    <origin rpy="-1.57079632679 0 -1.57079632679" xyz="0 0 0"/>
    <parent link="camera_infra2_frame"/>
    <child link="camera_infra2_optical_frame"/>
  </joint>
  <link name="camera_infra2_optical_frame"/>
  <!-- camera color joints and links -->
  <joint name="camera_color_joint" type="fixed">
    <origin rpy="0 0 0" xyz="0 0.015 0"/>
    <parent link="camera_link"/>
    <child link="camera_color_frame"/>
  </joint>
  <link name="camera_color_frame"/>
  <joint name="camera_color_optical_joint" type="fixed">
    <origin rpy="-1.57079632679 0 -1.57079632679" xyz="0 0 0"/>
    <parent link="camera_color_frame"/>
    <child link="camera_color_optical_frame"/>
  </joint>
  <link name="camera_color_optical_frame"/>
</robot>
